[2025-07-03T13:01:58.432+0000] {taskinstance.py:1956} INFO - Dependencies all met for dep_context=non-requeueable deps ti=<TaskInstance: merge_query_to_temp_logs.run_merge_query manual__2025-07-03T13:01:57.133677+00:00 [queued]>
[2025-07-03T13:01:58.437+0000] {taskinstance.py:1956} INFO - Dependencies all met for dep_context=requeueable deps ti=<TaskInstance: merge_query_to_temp_logs.run_merge_query manual__2025-07-03T13:01:57.133677+00:00 [queued]>
[2025-07-03T13:01:58.437+0000] {taskinstance.py:2170} INFO - Starting attempt 1 of 1
[2025-07-03T13:01:58.446+0000] {taskinstance.py:2191} INFO - Executing <Task(PythonOperator): run_merge_query> on 2025-07-03 13:01:57.133677+00:00
[2025-07-03T13:01:58.450+0000] {standard_task_runner.py:60} INFO - Started process 10107 to run task
[2025-07-03T13:01:58.451+0000] {standard_task_runner.py:87} INFO - Running: ['***', 'tasks', 'run', 'merge_query_to_temp_logs', 'run_merge_query', 'manual__2025-07-03T13:01:57.133677+00:00', '--job-id', '51', '--raw', '--subdir', 'DAGS_FOLDER/merge_query_dag.py', '--cfg-path', '/tmp/tmptf4qgeda']
[2025-07-03T13:01:58.452+0000] {standard_task_runner.py:88} INFO - Job 51: Subtask run_merge_query
[2025-07-03T13:01:58.487+0000] {task_command.py:423} INFO - Running <TaskInstance: merge_query_to_temp_logs.run_merge_query manual__2025-07-03T13:01:57.133677+00:00 [running]> on host 61fdbbb5a1a9
[2025-07-03T13:01:58.606+0000] {taskinstance.py:2480} INFO - Exporting env vars: AIRFLOW_CTX_DAG_OWNER='***' AIRFLOW_CTX_DAG_ID='merge_query_to_temp_logs' AIRFLOW_CTX_TASK_ID='run_merge_query' AIRFLOW_CTX_EXECUTION_DATE='2025-07-03T13:01:57.133677+00:00' AIRFLOW_CTX_TRY_NUMBER='1' AIRFLOW_CTX_DAG_RUN_ID='manual__2025-07-03T13:01:57.133677+00:00'
[2025-07-03T13:01:58.610+0000] {merge_query_dag.py:36} INFO - Executing 4 queries from the merged SQL file.
[2025-07-03T13:01:58.610+0000] {merge_query_dag.py:40} INFO - 
ðŸš€ Executing Query 3:
-- SELECT_QUERY_START
SELECT 
    PROJECT_ID, PROJECT_NAME, DEPARTMENT, START_DATE, END_DATE, BUDGET
FROM DEV_DB.DEV_SCHEMA.ATTENDANCE
WHERE START_DATE >= '2024-01-01'
ORDER BY START_DATE
[2025-07-03T13:01:58.623+0000] {base.py:83} INFO - Using connection ID 'snowflake_dev_conn' for task execution.
[2025-07-03T13:01:58.624+0000] {connection.py:370} INFO - Snowflake Connector for Python Version: 3.6.0, Python Version: 3.8.18, Platform: Linux-6.2.0-26-generic-x86_64-with-glibc2.34
[2025-07-03T13:01:58.624+0000] {connection.py:1171} INFO - This connection is in OCSP Fail Open Mode. TLS Certificates would be checked for validity and revocation status. Any other Certificate Revocation related exceptions or OCSP Responder failures would be disregarded in favor of connectivity.
[2025-07-03T13:01:59.593+0000] {cursor.py:1028} INFO - query: [ALTER SESSION SET autocommit=False]
[2025-07-03T13:01:59.896+0000] {cursor.py:1041} INFO - query execution done
[2025-07-03T13:01:59.896+0000] {cursor.py:1205} INFO - Number of results in first chunk: 1
[2025-07-03T13:01:59.896+0000] {sql.py:450} INFO - Running statement: -- SELECT_QUERY_START
SELECT 
    PROJECT_ID, PROJECT_NAME, DEPARTMENT, START_DATE, END_DATE, BUDGET
FROM DEV_DB.DEV_SCHEMA.ATTENDANCE
WHERE START_DATE >= '2024-01-01'
ORDER BY START_DATE, parameters: None
[2025-07-03T13:01:59.897+0000] {cursor.py:1028} INFO - query: [-- SELECT_QUERY_START SELECT PROJECT_ID, PROJECT_NAME, DEPARTMENT, START_DATE, E...]
[2025-07-03T13:02:00.199+0000] {cursor.py:1041} INFO - query execution done
[2025-07-03T13:02:00.204+0000] {connection.py:718} INFO - closed
[2025-07-03T13:02:00.407+0000] {connection.py:724} INFO - No async queries seem to be running, deleting session
[2025-07-03T13:02:00.612+0000] {taskinstance.py:2698} ERROR - Task failed with exception
Traceback (most recent call last):
  File "/home/airflow/.local/lib/python3.8/site-packages/airflow/models/taskinstance.py", line 433, in _execute_task
    result = execute_callable(context=context, **execute_callable_kwargs)
  File "/home/airflow/.local/lib/python3.8/site-packages/airflow/operators/python.py", line 199, in execute
    return_value = self.execute_callable()
  File "/home/airflow/.local/lib/python3.8/site-packages/airflow/operators/python.py", line 216, in execute_callable
    return self.python_callable(*self.op_args, **self.op_kwargs)
  File "/opt/airflow/dags/merge_query_dag.py", line 45, in merge_query
    hook.run(q)
  File "/home/airflow/.local/lib/python3.8/site-packages/airflow/providers/snowflake/hooks/snowflake.py", line 388, in run
    self._run_command(cur, sql_statement, parameters)
  File "/home/airflow/.local/lib/python3.8/site-packages/airflow/providers/common/sql/hooks/sql.py", line 455, in _run_command
    cur.execute(sql_statement)
  File "/home/airflow/.local/lib/python3.8/site-packages/snowflake/connector/cursor.py", line 1132, in execute
    Error.errorhandler_wrapper(self.connection, self, error_class, errvalue)
  File "/home/airflow/.local/lib/python3.8/site-packages/snowflake/connector/errors.py", line 290, in errorhandler_wrapper
    handed_over = Error.hand_to_other_handler(
  File "/home/airflow/.local/lib/python3.8/site-packages/snowflake/connector/errors.py", line 345, in hand_to_other_handler
    cursor.errorhandler(connection, cursor, error_class, error_value)
  File "/home/airflow/.local/lib/python3.8/site-packages/snowflake/connector/errors.py", line 221, in default_errorhandler
    raise error_class(
snowflake.connector.errors.ProgrammingError: 000904 (42000): 01bd710e-3201-c0df-000e-50720001f72a: SQL compilation error: error line 2 at position 4
invalid identifier 'PROJECT_ID'
[2025-07-03T13:02:00.624+0000] {taskinstance.py:1138} INFO - Marking task as FAILED. dag_id=merge_query_to_temp_logs, task_id=run_merge_query, execution_date=20250703T130157, start_date=20250703T130158, end_date=20250703T130200
[2025-07-03T13:02:00.637+0000] {standard_task_runner.py:107} ERROR - Failed to execute job 51 for task run_merge_query (000904 (42000): 01bd710e-3201-c0df-000e-50720001f72a: SQL compilation error: error line 2 at position 4
invalid identifier 'PROJECT_ID'; 10107)
[2025-07-03T13:02:00.673+0000] {local_task_job_runner.py:234} INFO - Task exited with return code 1
[2025-07-03T13:02:00.687+0000] {taskinstance.py:3280} INFO - 0 downstream tasks scheduled from follow-on schedule check
