[2025-07-08T13:51:10.093+0000] {taskinstance.py:1956} INFO - Dependencies all met for dep_context=non-requeueable deps ti=<TaskInstance: Titanic_upload_file_to_s3_dag.upload_sql_to_s3 manual__2025-07-08T13:51:09.511142+00:00 [queued]>
[2025-07-08T13:51:10.102+0000] {taskinstance.py:1956} INFO - Dependencies all met for dep_context=requeueable deps ti=<TaskInstance: Titanic_upload_file_to_s3_dag.upload_sql_to_s3 manual__2025-07-08T13:51:09.511142+00:00 [queued]>
[2025-07-08T13:51:10.102+0000] {taskinstance.py:2170} INFO - Starting attempt 1 of 1
[2025-07-08T13:51:10.116+0000] {taskinstance.py:2191} INFO - Executing <Task(PythonOperator): upload_sql_to_s3> on 2025-07-08 13:51:09.511142+00:00
[2025-07-08T13:51:10.122+0000] {standard_task_runner.py:60} INFO - Started process 13871 to run task
[2025-07-08T13:51:10.124+0000] {standard_task_runner.py:87} INFO - Running: ['***', 'tasks', 'run', 'Titanic_upload_file_to_s3_dag', 'upload_sql_to_s3', 'manual__2025-07-08T13:51:09.511142+00:00', '--job-id', '108', '--raw', '--subdir', 'DAGS_FOLDER/store_file_into_aws.py', '--cfg-path', '/tmp/tmpi0zs_wyi']
[2025-07-08T13:51:10.127+0000] {standard_task_runner.py:88} INFO - Job 108: Subtask upload_sql_to_s3
[2025-07-08T13:51:10.173+0000] {task_command.py:423} INFO - Running <TaskInstance: Titanic_upload_file_to_s3_dag.upload_sql_to_s3 manual__2025-07-08T13:51:09.511142+00:00 [running]> on host a6c4ed809f61
[2025-07-08T13:51:10.229+0000] {taskinstance.py:2480} INFO - Exporting env vars: AIRFLOW_CTX_DAG_EMAIL='manan.gupta@growexx.com' AIRFLOW_CTX_DAG_OWNER='***' AIRFLOW_CTX_DAG_ID='Titanic_upload_file_to_s3_dag' AIRFLOW_CTX_TASK_ID='upload_sql_to_s3' AIRFLOW_CTX_EXECUTION_DATE='2025-07-08T13:51:09.511142+00:00' AIRFLOW_CTX_TRY_NUMBER='1' AIRFLOW_CTX_DAG_RUN_ID='manual__2025-07-08T13:51:09.511142+00:00'
[2025-07-08T13:51:11.393+0000] {store_file_into_aws.py:40} ERROR - AWS credentials not found or invalid
[2025-07-08T13:51:11.394+0000] {taskinstance.py:2698} ERROR - Task failed with exception
Traceback (most recent call last):
  File "/home/airflow/.local/lib/python3.8/site-packages/boto3/s3/transfer.py", line 371, in upload_file
    future.result()
  File "/home/airflow/.local/lib/python3.8/site-packages/s3transfer/futures.py", line 103, in result
    return self._coordinator.result()
  File "/home/airflow/.local/lib/python3.8/site-packages/s3transfer/futures.py", line 266, in result
    raise self._exception
  File "/home/airflow/.local/lib/python3.8/site-packages/s3transfer/tasks.py", line 139, in __call__
    return self._execute_main(kwargs)
  File "/home/airflow/.local/lib/python3.8/site-packages/s3transfer/tasks.py", line 162, in _execute_main
    return_value = self._main(**kwargs)
  File "/home/airflow/.local/lib/python3.8/site-packages/s3transfer/upload.py", line 764, in _main
    client.put_object(Bucket=bucket, Key=key, Body=body, **extra_args)
  File "/home/airflow/.local/lib/python3.8/site-packages/botocore/client.py", line 553, in _api_call
    return self._make_api_call(operation_name, kwargs)
  File "/home/airflow/.local/lib/python3.8/site-packages/botocore/client.py", line 1009, in _make_api_call
    raise error_class(parsed_response, operation_name)
botocore.errorfactory.NoSuchBucket: An error occurred (NoSuchBucket) when calling the PutObject operation: The specified bucket does not exist

During handling of the above exception, another exception occurred:

Traceback (most recent call last):
  File "/home/airflow/.local/lib/python3.8/site-packages/airflow/models/taskinstance.py", line 433, in _execute_task
    result = execute_callable(context=context, **execute_callable_kwargs)
  File "/home/airflow/.local/lib/python3.8/site-packages/airflow/operators/python.py", line 199, in execute
    return_value = self.execute_callable()
  File "/home/airflow/.local/lib/python3.8/site-packages/airflow/operators/python.py", line 216, in execute_callable
    return self.python_callable(*self.op_args, **self.op_kwargs)
  File "/opt/airflow/dags/store_file_into_aws.py", line 41, in upload_to_s3
    raise e
  File "/opt/airflow/dags/store_file_into_aws.py", line 37, in upload_to_s3
    s3_client.upload_file(local_file_path, bucket_name, object_name)
  File "/home/airflow/.local/lib/python3.8/site-packages/boto3/s3/inject.py", line 145, in upload_file
    return transfer.upload_file(
  File "/home/airflow/.local/lib/python3.8/site-packages/boto3/s3/transfer.py", line 377, in upload_file
    raise S3UploadFailedError(
boto3.exceptions.S3UploadFailedError: Failed to upload /opt/***/scripts/Titanic-Dataset.csv to vonage-titanic-buckt/Titanic-Dataset.csv: An error occurred (NoSuchBucket) when calling the PutObject operation: The specified bucket does not exist
[2025-07-08T13:51:11.407+0000] {taskinstance.py:1138} INFO - Marking task as FAILED. dag_id=Titanic_upload_file_to_s3_dag, task_id=upload_sql_to_s3, execution_date=20250708T135109, start_date=20250708T135110, end_date=20250708T135111
[2025-07-08T13:51:11.409+0000] {logging_mixin.py:188} WARNING - /home/***/.local/lib/python3.8/site-packages/***/utils/context.py:207 AirflowContextDeprecationWarning: Accessing 'execution_date' from the template is deprecated and will be removed in a future version. Please use 'data_interval_start' or 'logical_date' instead.
[2025-07-08T13:51:11.416+0000] {logging_mixin.py:188} WARNING - /home/***/.local/lib/python3.8/site-packages/***/utils/email.py:154 RemovedInAirflow3Warning: Fetching SMTP credentials from configuration variables will be deprecated in a future release. Please set credentials using a connection instead.
[2025-07-08T13:51:11.417+0000] {email.py:270} INFO - Email alerting: attempt 1
[2025-07-08T13:51:12.101+0000] {email.py:281} INFO - Sent an alert email to ['manan.gupta@growexx.com', 'guptamanan567@gmail.com', 'yash.pandya@growexx.com']
[2025-07-08T13:51:12.546+0000] {standard_task_runner.py:107} ERROR - Failed to execute job 108 for task upload_sql_to_s3 (Failed to upload /opt/***/scripts/Titanic-Dataset.csv to vonage-titanic-buckt/Titanic-Dataset.csv: An error occurred (NoSuchBucket) when calling the PutObject operation: The specified bucket does not exist; 13871)
[2025-07-08T13:51:12.589+0000] {local_task_job_runner.py:234} INFO - Task exited with return code 1
[2025-07-08T13:51:12.606+0000] {taskinstance.py:3280} INFO - 0 downstream tasks scheduled from follow-on schedule check
