[2025-07-03T09:34:54.085+0000] {taskinstance.py:1956} INFO - Dependencies all met for dep_context=non-requeueable deps ti=<TaskInstance: merge_query_dag.run_merge_query manual__2025-07-03T09:34:53.197412+00:00 [queued]>
[2025-07-03T09:34:54.090+0000] {taskinstance.py:1956} INFO - Dependencies all met for dep_context=requeueable deps ti=<TaskInstance: merge_query_dag.run_merge_query manual__2025-07-03T09:34:53.197412+00:00 [queued]>
[2025-07-03T09:34:54.090+0000] {taskinstance.py:2170} INFO - Starting attempt 1 of 1
[2025-07-03T09:34:54.097+0000] {taskinstance.py:2191} INFO - Executing <Task(PythonOperator): run_merge_query> on 2025-07-03 09:34:53.197412+00:00
[2025-07-03T09:34:54.102+0000] {standard_task_runner.py:60} INFO - Started process 1218 to run task
[2025-07-03T09:34:54.104+0000] {standard_task_runner.py:87} INFO - Running: ['***', 'tasks', 'run', 'merge_query_dag', 'run_merge_query', 'manual__2025-07-03T09:34:53.197412+00:00', '--job-id', '35', '--raw', '--subdir', 'DAGS_FOLDER/merge_query_dag.py', '--cfg-path', '/tmp/tmp9_vr7v90']
[2025-07-03T09:34:54.105+0000] {standard_task_runner.py:88} INFO - Job 35: Subtask run_merge_query
[2025-07-03T09:34:54.136+0000] {task_command.py:423} INFO - Running <TaskInstance: merge_query_dag.run_merge_query manual__2025-07-03T09:34:53.197412+00:00 [running]> on host be92b7fd988a
[2025-07-03T09:34:54.192+0000] {taskinstance.py:2480} INFO - Exporting env vars: AIRFLOW_CTX_DAG_OWNER='***' AIRFLOW_CTX_DAG_ID='merge_query_dag' AIRFLOW_CTX_TASK_ID='run_merge_query' AIRFLOW_CTX_EXECUTION_DATE='2025-07-03T09:34:53.197412+00:00' AIRFLOW_CTX_TRY_NUMBER='1' AIRFLOW_CTX_DAG_RUN_ID='manual__2025-07-03T09:34:53.197412+00:00'
[2025-07-03T09:34:54.205+0000] {base.py:83} INFO - Using connection ID 'snowflake_dev_conn' for task execution.
[2025-07-03T09:34:54.206+0000] {connection.py:370} INFO - Snowflake Connector for Python Version: 3.6.0, Python Version: 3.8.18, Platform: Linux-6.2.0-26-generic-x86_64-with-glibc2.34
[2025-07-03T09:34:54.206+0000] {connection.py:1171} INFO - This connection is in OCSP Fail Open Mode. TLS Certificates would be checked for validity and revocation status. Any other Certificate Revocation related exceptions or OCSP Responder failures would be disregarded in favor of connectivity.
[2025-07-03T09:34:54.849+0000] {cursor.py:1028} INFO - query: [ALTER SESSION SET autocommit=False]
[2025-07-03T09:34:54.961+0000] {cursor.py:1041} INFO - query execution done
[2025-07-03T09:34:54.961+0000] {cursor.py:1205} INFO - Number of results in first chunk: 1
[2025-07-03T09:34:54.962+0000] {sql.py:450} INFO - Running statement: MERGE INTO DEV_DB.DEV_SCHEMA.EMPLOYEE AS TARGET
USING (SELECT 1 AS EMP_ID, 'TestUser' AS NAME, 28 AS AGE) AS SOURCE
ON TARGET.EMP_ID = SOURCE.EMP_ID
WHEN MATCHED THEN UPDATE SET NAME = SOURCE.NAME, AGE = SOURCE.AGE
WHEN NOT MATCHED THEN INSERT (EMP_ID, NAME, AGE)
VALUES (SOURCE.EMP_ID, SOURCE.NAME, SOURCE.AGE);, parameters: None
[2025-07-03T09:34:54.962+0000] {cursor.py:1028} INFO - query: [MERGE INTO DEV_DB.DEV_SCHEMA.EMPLOYEE AS TARGET USING (SELECT 1 AS EMP_ID, 'Test...]
[2025-07-03T09:34:55.256+0000] {cursor.py:1041} INFO - query execution done
[2025-07-03T09:34:55.262+0000] {connection.py:718} INFO - closed
[2025-07-03T09:34:55.344+0000] {connection.py:724} INFO - No async queries seem to be running, deleting session
[2025-07-03T09:34:55.440+0000] {taskinstance.py:2698} ERROR - Task failed with exception
Traceback (most recent call last):
  File "/home/airflow/.local/lib/python3.8/site-packages/airflow/models/taskinstance.py", line 433, in _execute_task
    result = execute_callable(context=context, **execute_callable_kwargs)
  File "/home/airflow/.local/lib/python3.8/site-packages/airflow/operators/python.py", line 199, in execute
    return_value = self.execute_callable()
  File "/home/airflow/.local/lib/python3.8/site-packages/airflow/operators/python.py", line 216, in execute_callable
    return self.python_callable(*self.op_args, **self.op_kwargs)
  File "/opt/airflow/dags/merge_query_dag.py", line 27, in merge_query
    hook.run(query)
  File "/home/airflow/.local/lib/python3.8/site-packages/airflow/providers/snowflake/hooks/snowflake.py", line 388, in run
    self._run_command(cur, sql_statement, parameters)
  File "/home/airflow/.local/lib/python3.8/site-packages/airflow/providers/common/sql/hooks/sql.py", line 455, in _run_command
    cur.execute(sql_statement)
  File "/home/airflow/.local/lib/python3.8/site-packages/snowflake/connector/cursor.py", line 1132, in execute
    Error.errorhandler_wrapper(self.connection, self, error_class, errvalue)
  File "/home/airflow/.local/lib/python3.8/site-packages/snowflake/connector/errors.py", line 290, in errorhandler_wrapper
    handed_over = Error.hand_to_other_handler(
  File "/home/airflow/.local/lib/python3.8/site-packages/snowflake/connector/errors.py", line 345, in hand_to_other_handler
    cursor.errorhandler(connection, cursor, error_class, error_value)
  File "/home/airflow/.local/lib/python3.8/site-packages/snowflake/connector/errors.py", line 221, in default_errorhandler
    raise error_class(
snowflake.connector.errors.ProgrammingError: 000904 (42000): 01bd703e-3201-c0df-000e-50720001f4d2: SQL compilation error: error line 5 at position 38
invalid identifier 'NAME'
[2025-07-03T09:34:55.451+0000] {taskinstance.py:1138} INFO - Marking task as FAILED. dag_id=merge_query_dag, task_id=run_merge_query, execution_date=20250703T093453, start_date=20250703T093454, end_date=20250703T093455
[2025-07-03T09:34:55.467+0000] {standard_task_runner.py:107} ERROR - Failed to execute job 35 for task run_merge_query (000904 (42000): 01bd703e-3201-c0df-000e-50720001f4d2: SQL compilation error: error line 5 at position 38
invalid identifier 'NAME'; 1218)
[2025-07-03T09:34:55.482+0000] {local_task_job_runner.py:234} INFO - Task exited with return code 1
[2025-07-03T09:34:55.504+0000] {taskinstance.py:3280} INFO - 0 downstream tasks scheduled from follow-on schedule check
