[2025-06-27T13:20:32.755+0000] {taskinstance.py:1956} INFO - Dependencies all met for dep_context=non-requeueable deps ti=<TaskInstance: simple_snowflake_dag.check_snowflake_version manual__2025-06-27T13:20:31.203035+00:00 [queued]>
[2025-06-27T13:20:32.764+0000] {taskinstance.py:1956} INFO - Dependencies all met for dep_context=requeueable deps ti=<TaskInstance: simple_snowflake_dag.check_snowflake_version manual__2025-06-27T13:20:31.203035+00:00 [queued]>
[2025-06-27T13:20:32.764+0000] {taskinstance.py:2170} INFO - Starting attempt 1 of 1
[2025-06-27T13:20:32.773+0000] {taskinstance.py:2191} INFO - Executing <Task(SnowflakeOperator): check_snowflake_version> on 2025-06-27 13:20:31.203035+00:00
[2025-06-27T13:20:32.779+0000] {standard_task_runner.py:60} INFO - Started process 12445 to run task
[2025-06-27T13:20:32.783+0000] {standard_task_runner.py:87} INFO - Running: ['***', 'tasks', 'run', 'simple_snowflake_dag', 'check_snowflake_version', 'manual__2025-06-27T13:20:31.203035+00:00', '--job-id', '9', '--raw', '--subdir', 'DAGS_FOLDER/snowflake_simple_dag.py', '--cfg-path', '/tmp/tmplqgoi9h0']
[2025-06-27T13:20:32.783+0000] {standard_task_runner.py:88} INFO - Job 9: Subtask check_snowflake_version
[2025-06-27T13:20:32.799+0000] {logging_mixin.py:188} WARNING - /home/***/.local/lib/python3.8/site-packages/***/settings.py:194 DeprecationWarning: The sql_alchemy_conn option in [core] has been moved to the sql_alchemy_conn option in [database] - the old setting has been used, but please update your config.
[2025-06-27T13:20:32.833+0000] {task_command.py:423} INFO - Running <TaskInstance: simple_snowflake_dag.check_snowflake_version manual__2025-06-27T13:20:31.203035+00:00 [running]> on host 4594cae8c2a2
[2025-06-27T13:20:32.910+0000] {taskinstance.py:2480} INFO - Exporting env vars: AIRFLOW_CTX_DAG_OWNER='***' AIRFLOW_CTX_DAG_ID='simple_snowflake_dag' AIRFLOW_CTX_TASK_ID='check_snowflake_version' AIRFLOW_CTX_EXECUTION_DATE='2025-06-27T13:20:31.203035+00:00' AIRFLOW_CTX_TRY_NUMBER='1' AIRFLOW_CTX_DAG_RUN_ID='manual__2025-06-27T13:20:31.203035+00:00'
[2025-06-27T13:20:32.912+0000] {sql.py:276} INFO - Executing: SELECT CURRENT_DATABASE();
[2025-06-27T13:20:32.920+0000] {base.py:83} INFO - Using connection ID 'my_snowflake_conn' for task execution.
[2025-06-27T13:20:32.930+0000] {base.py:83} INFO - Using connection ID 'my_snowflake_conn' for task execution.
[2025-06-27T13:20:32.931+0000] {connection.py:370} INFO - Snowflake Connector for Python Version: 3.6.0, Python Version: 3.8.18, Platform: Linux-6.2.0-26-generic-x86_64-with-glibc2.34
[2025-06-27T13:20:32.932+0000] {connection.py:1171} INFO - This connection is in OCSP Fail Open Mode. TLS Certificates would be checked for validity and revocation status. Any other Certificate Revocation related exceptions or OCSP Responder failures would be disregarded in favor of connectivity.
[2025-06-27T13:20:32.937+0000] {connectionpool.py:824} WARNING - Retrying (Retry(total=0, connect=None, read=None, redirect=None, status=None)) after connection broken by 'NewConnectionError('<snowflake.connector.vendored.urllib3.connection.HTTPSConnection object at 0x7fd3a49ee670>: Failed to establish a new connection: [Errno -2] Name or service not known')': /session/v1/login-request?request_id=80956bf5-001a-4217-a46c-e93d16813ff4&databaseName=AIRFLOW_PRACTICE&schemaName=PUBLIC&warehouse=COMPUTE_WH&roleName=ACCOUNTADMIN&request_guid=2c719525-3a5d-4b28-b1ec-ed96128b8863
[2025-06-27T13:20:33.947+0000] {connectionpool.py:824} WARNING - Retrying (Retry(total=0, connect=None, read=None, redirect=None, status=None)) after connection broken by 'NewConnectionError('<snowflake.connector.vendored.urllib3.connection.HTTPSConnection object at 0x7fd3a491c0d0>: Failed to establish a new connection: [Errno -2] Name or service not known')': /session/v1/login-request?request_id=264c135b-5154-43ed-90a1-ee52f97eef76&databaseName=AIRFLOW_PRACTICE&schemaName=PUBLIC&warehouse=COMPUTE_WH&roleName=ACCOUNTADMIN&request_guid=1531bade-e594-48d3-a8c5-c998f4e2fc38
[2025-06-27T13:20:33.952+0000] {taskinstance.py:2698} ERROR - Task failed with exception
Traceback (most recent call last):
  File "/home/airflow/.local/lib/python3.8/site-packages/snowflake/connector/vendored/urllib3/connection.py", line 174, in _new_conn
    conn = connection.create_connection(
  File "/home/airflow/.local/lib/python3.8/site-packages/snowflake/connector/vendored/urllib3/util/connection.py", line 79, in create_connection
    for res in socket.getaddrinfo(host, port, family, socket.SOCK_STREAM):
  File "/usr/local/lib/python3.8/socket.py", line 918, in getaddrinfo
    for res in _socket.getaddrinfo(host, port, family, type, proto, flags):
socket.gaierror: [Errno -2] Name or service not known

During handling of the above exception, another exception occurred:

Traceback (most recent call last):
  File "/home/airflow/.local/lib/python3.8/site-packages/snowflake/connector/vendored/urllib3/connectionpool.py", line 715, in urlopen
    httplib_response = self._make_request(
  File "/home/airflow/.local/lib/python3.8/site-packages/snowflake/connector/vendored/urllib3/connectionpool.py", line 404, in _make_request
    self._validate_conn(conn)
  File "/home/airflow/.local/lib/python3.8/site-packages/snowflake/connector/vendored/urllib3/connectionpool.py", line 1058, in _validate_conn
    conn.connect()
  File "/home/airflow/.local/lib/python3.8/site-packages/snowflake/connector/vendored/urllib3/connection.py", line 363, in connect
    self.sock = conn = self._new_conn()
  File "/home/airflow/.local/lib/python3.8/site-packages/snowflake/connector/vendored/urllib3/connection.py", line 186, in _new_conn
    raise NewConnectionError(
snowflake.connector.vendored.urllib3.exceptions.NewConnectionError: <snowflake.connector.vendored.urllib3.connection.HTTPSConnection object at 0x7fd3a49f1580>: Failed to establish a new connection: [Errno -2] Name or service not known

During handling of the above exception, another exception occurred:

Traceback (most recent call last):
  File "/home/airflow/.local/lib/python3.8/site-packages/snowflake/connector/vendored/requests/adapters.py", line 486, in send
    resp = conn.urlopen(
  File "/home/airflow/.local/lib/python3.8/site-packages/snowflake/connector/vendored/urllib3/connectionpool.py", line 827, in urlopen
    return self.urlopen(
  File "/home/airflow/.local/lib/python3.8/site-packages/snowflake/connector/vendored/urllib3/connectionpool.py", line 799, in urlopen
    retries = retries.increment(
  File "/home/airflow/.local/lib/python3.8/site-packages/snowflake/connector/vendored/urllib3/util/retry.py", line 592, in increment
    raise MaxRetryError(_pool, url, error or ResponseError(cause))
snowflake.connector.vendored.urllib3.exceptions.MaxRetryError: HTTPSConnectionPool(host='zm46186.asia%20pacific%20(singapore).snowflakecomputing.com', port=443): Max retries exceeded with url: /session/v1/login-request?request_id=80956bf5-001a-4217-a46c-e93d16813ff4&databaseName=AIRFLOW_PRACTICE&schemaName=PUBLIC&warehouse=COMPUTE_WH&roleName=ACCOUNTADMIN&request_guid=2c719525-3a5d-4b28-b1ec-ed96128b8863 (Caused by NewConnectionError('<snowflake.connector.vendored.urllib3.connection.HTTPSConnection object at 0x7fd3a49f1580>: Failed to establish a new connection: [Errno -2] Name or service not known'))

During handling of the above exception, another exception occurred:

Traceback (most recent call last):
  File "/home/airflow/.local/lib/python3.8/site-packages/snowflake/connector/network.py", line 1073, in _request_exec
    raw_ret = session.request(
  File "/home/airflow/.local/lib/python3.8/site-packages/snowflake/connector/vendored/requests/sessions.py", line 589, in request
    resp = self.send(prep, **send_kwargs)
  File "/home/airflow/.local/lib/python3.8/site-packages/snowflake/connector/vendored/requests/sessions.py", line 703, in send
    r = adapter.send(request, **kwargs)
  File "/home/airflow/.local/lib/python3.8/site-packages/snowflake/connector/vendored/requests/adapters.py", line 519, in send
    raise ConnectionError(e, request=request)
snowflake.connector.vendored.requests.exceptions.ConnectionError: HTTPSConnectionPool(host='zm46186.asia%20pacific%20(singapore).snowflakecomputing.com', port=443): Max retries exceeded with url: /session/v1/login-request?request_id=80956bf5-001a-4217-a46c-e93d16813ff4&databaseName=AIRFLOW_PRACTICE&schemaName=PUBLIC&warehouse=COMPUTE_WH&roleName=ACCOUNTADMIN&request_guid=2c719525-3a5d-4b28-b1ec-ed96128b8863 (Caused by NewConnectionError('<snowflake.connector.vendored.urllib3.connection.HTTPSConnection object at 0x7fd3a49f1580>: Failed to establish a new connection: [Errno -2] Name or service not known'))

During handling of the above exception, another exception occurred:

Traceback (most recent call last):
  File "/home/airflow/.local/lib/python3.8/site-packages/snowflake/connector/connection.py", line 1305, in _authenticate
    auth.authenticate(
  File "/home/airflow/.local/lib/python3.8/site-packages/snowflake/connector/auth/_auth.py", line 250, in authenticate
    ret = self._rest._post_request(
  File "/home/airflow/.local/lib/python3.8/site-packages/snowflake/connector/network.py", line 729, in _post_request
    ret = self.fetch(
  File "/home/airflow/.local/lib/python3.8/site-packages/snowflake/connector/network.py", line 838, in fetch
    ret = self._request_exec_wrapper(
  File "/home/airflow/.local/lib/python3.8/site-packages/snowflake/connector/network.py", line 974, in _request_exec_wrapper
    raise e
  File "/home/airflow/.local/lib/python3.8/site-packages/snowflake/connector/network.py", line 879, in _request_exec_wrapper
    return_object = self._request_exec(
  File "/home/airflow/.local/lib/python3.8/site-packages/snowflake/connector/network.py", line 1167, in _request_exec
    raise OperationalError(
snowflake.connector.errors.OperationalError: 251011: 251011: ConnectionTimeout occurred during login. Will be handled by authenticator

The above exception was the direct cause of the following exception:

Traceback (most recent call last):
  File "/home/airflow/.local/lib/python3.8/site-packages/airflow/models/taskinstance.py", line 433, in _execute_task
    result = execute_callable(context=context, **execute_callable_kwargs)
  File "/home/airflow/.local/lib/python3.8/site-packages/airflow/providers/common/sql/operators/sql.py", line 282, in execute
    output = hook.run(
  File "/home/airflow/.local/lib/python3.8/site-packages/airflow/providers/snowflake/hooks/snowflake.py", line 382, in run
    with closing(self.get_conn()) as conn:
  File "/home/airflow/.local/lib/python3.8/site-packages/airflow/providers/snowflake/hooks/snowflake.py", line 276, in get_conn
    conn = connector.connect(**conn_config)
  File "/home/airflow/.local/lib/python3.8/site-packages/snowflake/connector/__init__.py", line 54, in Connect
    return SnowflakeConnection(**kwargs)
  File "/home/airflow/.local/lib/python3.8/site-packages/snowflake/connector/connection.py", line 413, in __init__
    self.connect(**kwargs)
  File "/home/airflow/.local/lib/python3.8/site-packages/snowflake/connector/connection.py", line 703, in connect
    self.__open_connection()
  File "/home/airflow/.local/lib/python3.8/site-packages/snowflake/connector/connection.py", line 1006, in __open_connection
    self.authenticate_with_retry(self.auth_class)
  File "/home/airflow/.local/lib/python3.8/site-packages/snowflake/connector/connection.py", line 1277, in authenticate_with_retry
    self._authenticate(auth_instance)
  File "/home/airflow/.local/lib/python3.8/site-packages/snowflake/connector/connection.py", line 1349, in _authenticate
    raise auth_op from e
  File "/home/airflow/.local/lib/python3.8/site-packages/snowflake/connector/connection.py", line 1326, in _authenticate
    auth_instance.handle_timeout(
  File "/home/airflow/.local/lib/python3.8/site-packages/snowflake/connector/auth/by_plugin.py", line 212, in handle_timeout
    raise error
snowflake.connector.errors.OperationalError: 250001: 250001: Could not connect to Snowflake backend after 2 attempt(s).Aborting
[2025-06-27T13:20:33.962+0000] {taskinstance.py:1138} INFO - Marking task as FAILED. dag_id=simple_snowflake_dag, task_id=check_snowflake_version, execution_date=20250627T132031, start_date=20250627T132032, end_date=20250627T132033
[2025-06-27T13:20:33.977+0000] {standard_task_runner.py:107} ERROR - Failed to execute job 9 for task check_snowflake_version (250001: 250001: Could not connect to Snowflake backend after 2 attempt(s).Aborting; 12445)
[2025-06-27T13:20:34.001+0000] {local_task_job_runner.py:234} INFO - Task exited with return code 1
[2025-06-27T13:20:34.024+0000] {taskinstance.py:3280} INFO - 0 downstream tasks scheduled from follow-on schedule check
