[2025-06-30T07:50:22.214+0000] {taskinstance.py:1956} INFO - Dependencies all met for dep_context=non-requeueable deps ti=<TaskInstance: simple_snowflake_dag.log_snowflake_database manual__2025-06-30T07:50:21.322671+00:00 [queued]>
[2025-06-30T07:50:22.219+0000] {taskinstance.py:1956} INFO - Dependencies all met for dep_context=requeueable deps ti=<TaskInstance: simple_snowflake_dag.log_snowflake_database manual__2025-06-30T07:50:21.322671+00:00 [queued]>
[2025-06-30T07:50:22.219+0000] {taskinstance.py:2170} INFO - Starting attempt 1 of 1
[2025-06-30T07:50:22.227+0000] {taskinstance.py:2191} INFO - Executing <Task(PythonOperator): log_snowflake_database> on 2025-06-30 07:50:21.322671+00:00
[2025-06-30T07:50:22.232+0000] {standard_task_runner.py:60} INFO - Started process 207 to run task
[2025-06-30T07:50:22.234+0000] {standard_task_runner.py:87} INFO - Running: ['***', 'tasks', 'run', 'simple_snowflake_dag', 'log_snowflake_database', 'manual__2025-06-30T07:50:21.322671+00:00', '--job-id', '37', '--raw', '--subdir', 'DAGS_FOLDER/snowflake_simple_dag.py', '--cfg-path', '/tmp/tmpci6zfkwx']
[2025-06-30T07:50:22.235+0000] {standard_task_runner.py:88} INFO - Job 37: Subtask log_snowflake_database
[2025-06-30T07:50:22.248+0000] {logging_mixin.py:188} WARNING - /home/***/.local/lib/python3.8/site-packages/***/settings.py:194 DeprecationWarning: The sql_alchemy_conn option in [core] has been moved to the sql_alchemy_conn option in [database] - the old setting has been used, but please update your config.
[2025-06-30T07:50:22.285+0000] {task_command.py:423} INFO - Running <TaskInstance: simple_snowflake_dag.log_snowflake_database manual__2025-06-30T07:50:21.322671+00:00 [running]> on host b546b068babc
[2025-06-30T07:50:22.354+0000] {taskinstance.py:2480} INFO - Exporting env vars: AIRFLOW_CTX_DAG_OWNER='***' AIRFLOW_CTX_DAG_ID='simple_snowflake_dag' AIRFLOW_CTX_TASK_ID='log_snowflake_database' AIRFLOW_CTX_EXECUTION_DATE='2025-06-30T07:50:21.322671+00:00' AIRFLOW_CTX_TRY_NUMBER='1' AIRFLOW_CTX_DAG_RUN_ID='manual__2025-06-30T07:50:21.322671+00:00'
[2025-06-30T07:50:22.365+0000] {taskinstance.py:2698} ERROR - Task failed with exception
Traceback (most recent call last):
  File "/home/airflow/.local/lib/python3.8/site-packages/airflow/models/taskinstance.py", line 433, in _execute_task
    result = execute_callable(context=context, **execute_callable_kwargs)
  File "/home/airflow/.local/lib/python3.8/site-packages/airflow/operators/python.py", line 199, in execute
    return_value = self.execute_callable()
  File "/home/airflow/.local/lib/python3.8/site-packages/airflow/operators/python.py", line 216, in execute_callable
    return self.python_callable(*self.op_args, **self.op_kwargs)
  File "/opt/airflow/dags/snowflake_simple_dag.py", line 11, in print_current_database
    conn = hook.get_conn()
  File "/home/airflow/.local/lib/python3.8/site-packages/airflow/providers/snowflake/hooks/snowflake.py", line 275, in get_conn
    conn_config = self._get_conn_params()
  File "/home/airflow/.local/lib/python3.8/site-packages/airflow/providers/snowflake/hooks/snowflake.py", line 183, in _get_conn_params
    conn = self.get_connection(self.snowflake_conn_id)  # type: ignore[attr-defined]
  File "/home/airflow/.local/lib/python3.8/site-packages/airflow/hooks/base.py", line 82, in get_connection
    conn = Connection.get_connection_from_secrets(conn_id)
  File "/home/airflow/.local/lib/python3.8/site-packages/airflow/models/connection.py", line 479, in get_connection_from_secrets
    raise AirflowNotFoundException(f"The conn_id `{conn_id}` isn't defined")
airflow.exceptions.AirflowNotFoundException: The conn_id `snowflake_dev_conn` isn't defined
[2025-06-30T07:50:22.368+0000] {taskinstance.py:1138} INFO - Marking task as FAILED. dag_id=simple_snowflake_dag, task_id=log_snowflake_database, execution_date=20250630T075021, start_date=20250630T075022, end_date=20250630T075022
[2025-06-30T07:50:22.374+0000] {standard_task_runner.py:107} ERROR - Failed to execute job 37 for task log_snowflake_database (The conn_id `snowflake_dev_conn` isn't defined; 207)
[2025-06-30T07:50:22.407+0000] {local_task_job_runner.py:234} INFO - Task exited with return code 1
[2025-06-30T07:50:22.432+0000] {taskinstance.py:3280} INFO - 0 downstream tasks scheduled from follow-on schedule check
