[2025-06-28T05:03:28.647+0000] {taskinstance.py:1956} INFO - Dependencies all met for dep_context=non-requeueable deps ti=<TaskInstance: simple_snowflake_dag.check_snowflake_version manual__2025-06-28T05:03:27.337488+00:00 [queued]>
[2025-06-28T05:03:28.652+0000] {taskinstance.py:1956} INFO - Dependencies all met for dep_context=requeueable deps ti=<TaskInstance: simple_snowflake_dag.check_snowflake_version manual__2025-06-28T05:03:27.337488+00:00 [queued]>
[2025-06-28T05:03:28.652+0000] {taskinstance.py:2170} INFO - Starting attempt 1 of 1
[2025-06-28T05:03:28.661+0000] {taskinstance.py:2191} INFO - Executing <Task(SnowflakeOperator): check_snowflake_version> on 2025-06-28 05:03:27.337488+00:00
[2025-06-28T05:03:28.664+0000] {standard_task_runner.py:60} INFO - Started process 491 to run task
[2025-06-28T05:03:28.666+0000] {standard_task_runner.py:87} INFO - Running: ['***', 'tasks', 'run', 'simple_snowflake_dag', 'check_snowflake_version', 'manual__2025-06-28T05:03:27.337488+00:00', '--job-id', '15', '--raw', '--subdir', 'DAGS_FOLDER/snowflake_simple_dag.py', '--cfg-path', '/tmp/tmp53m_s132']
[2025-06-28T05:03:28.667+0000] {standard_task_runner.py:88} INFO - Job 15: Subtask check_snowflake_version
[2025-06-28T05:03:28.676+0000] {logging_mixin.py:188} WARNING - /home/***/.local/lib/python3.8/site-packages/***/settings.py:194 DeprecationWarning: The sql_alchemy_conn option in [core] has been moved to the sql_alchemy_conn option in [database] - the old setting has been used, but please update your config.
[2025-06-28T05:03:28.701+0000] {task_command.py:423} INFO - Running <TaskInstance: simple_snowflake_dag.check_snowflake_version manual__2025-06-28T05:03:27.337488+00:00 [running]> on host 49f1fc066ba8
[2025-06-28T05:03:28.756+0000] {taskinstance.py:2480} INFO - Exporting env vars: AIRFLOW_CTX_DAG_OWNER='***' AIRFLOW_CTX_DAG_ID='simple_snowflake_dag' AIRFLOW_CTX_TASK_ID='check_snowflake_version' AIRFLOW_CTX_EXECUTION_DATE='2025-06-28T05:03:27.337488+00:00' AIRFLOW_CTX_TRY_NUMBER='1' AIRFLOW_CTX_DAG_RUN_ID='manual__2025-06-28T05:03:27.337488+00:00'
[2025-06-28T05:03:28.757+0000] {sql.py:276} INFO - Executing: SELECT CURRENT_DATABASE();
[2025-06-28T05:03:28.769+0000] {base.py:83} INFO - Using connection ID 'my_snowflake_conn' for task execution.
[2025-06-28T05:03:28.780+0000] {base.py:83} INFO - Using connection ID 'my_snowflake_conn' for task execution.
[2025-06-28T05:03:28.780+0000] {connection.py:370} INFO - Snowflake Connector for Python Version: 3.6.0, Python Version: 3.8.18, Platform: Linux-6.2.0-26-generic-x86_64-with-glibc2.34
[2025-06-28T05:03:28.781+0000] {connection.py:1171} INFO - This connection is in OCSP Fail Open Mode. TLS Certificates would be checked for validity and revocation status. Any other Certificate Revocation related exceptions or OCSP Responder failures would be disregarded in favor of connectivity.
[2025-06-28T05:03:29.822+0000] {connection.py:547} WARNING - Certificate did not match expected hostname: wwwrzod-zm46186.ho62902.aws.snowflakecomputing.com. Certificate: {'subject': ((('commonName', '*.prod3.us-west-2.snowflakecomputing.com'),),), 'subjectAltName': [('DNS', '*.prod3.us-west-2.snowflakecomputing.com'), ('DNS', '*.us-west-2.snowflakecomputing.com'), ('DNS', '*.global.snowflakecomputing.com'), ('DNS', '*.snowflakecomputing.com'), ('DNS', '*.prod3.us-west-2.aws.snowflakecomputing.com')]}
[2025-06-28T05:03:29.822+0000] {connectionpool.py:824} WARNING - Retrying (Retry(total=0, connect=None, read=None, redirect=None, status=None)) after connection broken by 'SSLError(CertificateError("hostname 'wwwrzod-zm46186.ho62902.aws.snowflakecomputing.com' doesn't match either of '*.prod3.us-west-2.snowflakecomputing.com', '*.us-west-2.snowflakecomputing.com', '*.global.snowflakecomputing.com', '*.snowflakecomputing.com', '*.prod3.us-west-2.aws.snowflakecomputing.com'"))': /session/v1/login-request?request_id=e57a582b-4650-4859-bfd4-f662ff331986&databaseName=AIRFLOW_PRACTICE&schemaName=PUBLIC&warehouse=COMPUTE_WH&roleName=ACCOUNTADMIN&request_guid=5ee9ada2-5d94-40a8-88c0-0b21840e737d
[2025-06-28T05:03:30.823+0000] {connection.py:547} WARNING - Certificate did not match expected hostname: wwwrzod-zm46186.ho62902.aws.snowflakecomputing.com. Certificate: {'subject': ((('commonName', '*.prod3.us-west-2.snowflakecomputing.com'),),), 'subjectAltName': [('DNS', '*.prod3.us-west-2.snowflakecomputing.com'), ('DNS', '*.us-west-2.snowflakecomputing.com'), ('DNS', '*.global.snowflakecomputing.com'), ('DNS', '*.snowflakecomputing.com'), ('DNS', '*.prod3.us-west-2.aws.snowflakecomputing.com')]}
[2025-06-28T05:03:30.825+0000] {network.py:1024} ERROR - Failed to get the response. Hanging? method: post, url: https://WWWRZOD-ZM46186.HO62902.AWS.snowflakecomputing.com:443/session/v1/login-request?request_id=e57a582b-4650-4859-bfd4-f662ff331986&databaseName=AIRFLOW_PRACTICE&schemaName=PUBLIC&warehouse=COMPUTE_WH&roleName=ACCOUNTADMIN&request_guid=5ee9ada2-5d94-40a8-88c0-0b21840e737d, headers:{'Content-Type': 'application/json', 'accept': 'application/snowflake', 'User-Agent': 'PythonConnector/3.6.0 (Linux-6.2.0-26-generic-x86_64-with-glibc2.34) CPython/3.8.18', 'Content-Encoding': 'gzip'}, data: {"data": {"CLIENT_APP_ID": "PythonConnector", "CLIENT_APP_VERSION": "3.6.0", "SVN_REVISION": null, "ACCOUNT_NAME": "WWWRZOD-ZM46186", "LOGIN_NAME": "MANAN6351", "CLIENT_ENVIRONMENT": {"APPLICATION": "AIRFLOW", "OS": "Linux", "OS_VERSION": "Linux-6.2.0-26-generic-x86_64-with-glibc2.34", "PYTHON_VERSION": "3.8.18", "PYTHON_RUNTIME": "CPython", "PYTHON_COMPILER": "GCC 12.2.0", "OCSP_MODE": "FAIL_OPEN", "TRACING": 20, "LOGIN_TIMEOUT": null, "NETWORK_TIMEOUT": null, "SOCKET_TIMEOUT": null}, "PASSWORD": "**** "SESSION_PARAMETERS": {"CLIENT_PREFETCH_THREADS": 4}}}
[2025-06-28T05:03:32.776+0000] {connection.py:547} WARNING - Certificate did not match expected hostname: wwwrzod-zm46186.ho62902.aws.snowflakecomputing.com. Certificate: {'subject': ((('commonName', '*.prod3.us-west-2.snowflakecomputing.com'),),), 'subjectAltName': [('DNS', '*.prod3.us-west-2.snowflakecomputing.com'), ('DNS', '*.us-west-2.snowflakecomputing.com'), ('DNS', '*.global.snowflakecomputing.com'), ('DNS', '*.snowflakecomputing.com'), ('DNS', '*.prod3.us-west-2.aws.snowflakecomputing.com')]}
[2025-06-28T05:03:32.776+0000] {connectionpool.py:824} WARNING - Retrying (Retry(total=0, connect=None, read=None, redirect=None, status=None)) after connection broken by 'SSLError(CertificateError("hostname 'wwwrzod-zm46186.ho62902.aws.snowflakecomputing.com' doesn't match either of '*.prod3.us-west-2.snowflakecomputing.com', '*.us-west-2.snowflakecomputing.com', '*.global.snowflakecomputing.com', '*.snowflakecomputing.com', '*.prod3.us-west-2.aws.snowflakecomputing.com'"))': /session/v1/login-request?request_id=dd9a0f82-4503-4e28-a940-bf4804ec7317&databaseName=AIRFLOW_PRACTICE&schemaName=PUBLIC&warehouse=COMPUTE_WH&roleName=ACCOUNTADMIN&request_guid=673fed86-3e29-4580-9095-823aa9fce611
[2025-06-28T05:03:33.696+0000] {connection.py:547} WARNING - Certificate did not match expected hostname: wwwrzod-zm46186.ho62902.aws.snowflakecomputing.com. Certificate: {'subject': ((('commonName', '*.prod3.us-west-2.snowflakecomputing.com'),),), 'subjectAltName': [('DNS', '*.prod3.us-west-2.snowflakecomputing.com'), ('DNS', '*.us-west-2.snowflakecomputing.com'), ('DNS', '*.global.snowflakecomputing.com'), ('DNS', '*.snowflakecomputing.com'), ('DNS', '*.prod3.us-west-2.aws.snowflakecomputing.com')]}
[2025-06-28T05:03:33.698+0000] {network.py:1024} ERROR - Failed to get the response. Hanging? method: post, url: https://WWWRZOD-ZM46186.HO62902.AWS.snowflakecomputing.com:443/session/v1/login-request?request_id=dd9a0f82-4503-4e28-a940-bf4804ec7317&databaseName=AIRFLOW_PRACTICE&schemaName=PUBLIC&warehouse=COMPUTE_WH&roleName=ACCOUNTADMIN&request_guid=673fed86-3e29-4580-9095-823aa9fce611, headers:{'Content-Type': 'application/json', 'accept': 'application/snowflake', 'User-Agent': 'PythonConnector/3.6.0 (Linux-6.2.0-26-generic-x86_64-with-glibc2.34) CPython/3.8.18', 'Content-Encoding': 'gzip'}, data: {"data": {"CLIENT_APP_ID": "PythonConnector", "CLIENT_APP_VERSION": "3.6.0", "SVN_REVISION": null, "ACCOUNT_NAME": "WWWRZOD-ZM46186", "LOGIN_NAME": "MANAN6351", "CLIENT_ENVIRONMENT": {"APPLICATION": "AIRFLOW", "OS": "Linux", "OS_VERSION": "Linux-6.2.0-26-generic-x86_64-with-glibc2.34", "PYTHON_VERSION": "3.8.18", "PYTHON_RUNTIME": "CPython", "PYTHON_COMPILER": "GCC 12.2.0", "OCSP_MODE": "FAIL_OPEN", "TRACING": 20, "LOGIN_TIMEOUT": null, "NETWORK_TIMEOUT": null, "SOCKET_TIMEOUT": null}, "PASSWORD": "**** "SESSION_PARAMETERS": {"CLIENT_PREFETCH_THREADS": 4}}}
[2025-06-28T05:03:33.699+0000] {taskinstance.py:2698} ERROR - Task failed with exception
Traceback (most recent call last):
  File "/home/airflow/.local/lib/python3.8/site-packages/snowflake/connector/connection.py", line 1305, in _authenticate
    auth.authenticate(
  File "/home/airflow/.local/lib/python3.8/site-packages/snowflake/connector/auth/_auth.py", line 250, in authenticate
    ret = self._rest._post_request(
  File "/home/airflow/.local/lib/python3.8/site-packages/snowflake/connector/network.py", line 729, in _post_request
    ret = self.fetch(
  File "/home/airflow/.local/lib/python3.8/site-packages/snowflake/connector/network.py", line 838, in fetch
    ret = self._request_exec_wrapper(
  File "/home/airflow/.local/lib/python3.8/site-packages/snowflake/connector/network.py", line 974, in _request_exec_wrapper
    raise e
  File "/home/airflow/.local/lib/python3.8/site-packages/snowflake/connector/network.py", line 890, in _request_exec_wrapper
    self._handle_unknown_error(method, full_url, headers, data, conn)
  File "/home/airflow/.local/lib/python3.8/site-packages/snowflake/connector/network.py", line 1029, in _handle_unknown_error
    Error.errorhandler_wrapper(
  File "/home/airflow/.local/lib/python3.8/site-packages/snowflake/connector/errors.py", line 290, in errorhandler_wrapper
    handed_over = Error.hand_to_other_handler(
  File "/home/airflow/.local/lib/python3.8/site-packages/snowflake/connector/errors.py", line 348, in hand_to_other_handler
    connection.errorhandler(connection, cursor, error_class, error_value)
  File "/home/airflow/.local/lib/python3.8/site-packages/snowflake/connector/errors.py", line 221, in default_errorhandler
    raise error_class(
snowflake.connector.errors.OperationalError: 250003: 250003: Failed to get the response. Hanging? method: post, url: https://WWWRZOD-ZM46186.HO62902.AWS.snowflakecomputing.com:443/session/v1/login-request?request_id=e57a582b-4650-4859-bfd4-f662ff331986&databaseName=AIRFLOW_PRACTICE&schemaName=PUBLIC&warehouse=COMPUTE_WH&roleName=ACCOUNTADMIN&request_guid=5ee9ada2-5d94-40a8-88c0-0b21840e737d

The above exception was the direct cause of the following exception:

Traceback (most recent call last):
  File "/home/airflow/.local/lib/python3.8/site-packages/airflow/models/taskinstance.py", line 433, in _execute_task
    result = execute_callable(context=context, **execute_callable_kwargs)
  File "/home/airflow/.local/lib/python3.8/site-packages/airflow/providers/common/sql/operators/sql.py", line 282, in execute
    output = hook.run(
  File "/home/airflow/.local/lib/python3.8/site-packages/airflow/providers/snowflake/hooks/snowflake.py", line 382, in run
    with closing(self.get_conn()) as conn:
  File "/home/airflow/.local/lib/python3.8/site-packages/airflow/providers/snowflake/hooks/snowflake.py", line 276, in get_conn
    conn = connector.connect(**conn_config)
  File "/home/airflow/.local/lib/python3.8/site-packages/snowflake/connector/__init__.py", line 54, in Connect
    return SnowflakeConnection(**kwargs)
  File "/home/airflow/.local/lib/python3.8/site-packages/snowflake/connector/connection.py", line 413, in __init__
    self.connect(**kwargs)
  File "/home/airflow/.local/lib/python3.8/site-packages/snowflake/connector/connection.py", line 703, in connect
    self.__open_connection()
  File "/home/airflow/.local/lib/python3.8/site-packages/snowflake/connector/connection.py", line 1006, in __open_connection
    self.authenticate_with_retry(self.auth_class)
  File "/home/airflow/.local/lib/python3.8/site-packages/snowflake/connector/connection.py", line 1277, in authenticate_with_retry
    self._authenticate(auth_instance)
  File "/home/airflow/.local/lib/python3.8/site-packages/snowflake/connector/connection.py", line 1349, in _authenticate
    raise auth_op from e
  File "/home/airflow/.local/lib/python3.8/site-packages/snowflake/connector/connection.py", line 1326, in _authenticate
    auth_instance.handle_timeout(
  File "/home/airflow/.local/lib/python3.8/site-packages/snowflake/connector/auth/by_plugin.py", line 212, in handle_timeout
    raise error
snowflake.connector.errors.OperationalError: 250001: 250001: Could not connect to Snowflake backend after 2 attempt(s).Aborting
[2025-06-28T05:03:33.704+0000] {taskinstance.py:1138} INFO - Marking task as FAILED. dag_id=simple_snowflake_dag, task_id=check_snowflake_version, execution_date=20250628T050327, start_date=20250628T050328, end_date=20250628T050333
[2025-06-28T05:03:33.711+0000] {standard_task_runner.py:107} ERROR - Failed to execute job 15 for task check_snowflake_version (250001: 250001: Could not connect to Snowflake backend after 2 attempt(s).Aborting; 491)
[2025-06-28T05:03:33.729+0000] {local_task_job_runner.py:234} INFO - Task exited with return code 1
[2025-06-28T05:03:33.755+0000] {taskinstance.py:3280} INFO - 0 downstream tasks scheduled from follow-on schedule check
