[2025-06-27T12:56:42.260+0000] {taskinstance.py:1956} INFO - Dependencies all met for dep_context=non-requeueable deps ti=<TaskInstance: simple_snowflake_dag.check_snowflake_version manual__2025-06-27T12:56:40.724097+00:00 [queued]>
[2025-06-27T12:56:42.267+0000] {taskinstance.py:1956} INFO - Dependencies all met for dep_context=requeueable deps ti=<TaskInstance: simple_snowflake_dag.check_snowflake_version manual__2025-06-27T12:56:40.724097+00:00 [queued]>
[2025-06-27T12:56:42.268+0000] {taskinstance.py:2170} INFO - Starting attempt 1 of 1
[2025-06-27T12:56:42.279+0000] {taskinstance.py:2191} INFO - Executing <Task(SnowflakeOperator): check_snowflake_version> on 2025-06-27 12:56:40.724097+00:00
[2025-06-27T12:56:42.284+0000] {standard_task_runner.py:60} INFO - Started process 610 to run task
[2025-06-27T12:56:42.287+0000] {standard_task_runner.py:87} INFO - Running: ['***', 'tasks', 'run', 'simple_snowflake_dag', 'check_snowflake_version', 'manual__2025-06-27T12:56:40.724097+00:00', '--job-id', '8', '--raw', '--subdir', 'DAGS_FOLDER/snowflake_simple_dag.py', '--cfg-path', '/tmp/tmpjzwgcoxv']
[2025-06-27T12:56:42.288+0000] {standard_task_runner.py:88} INFO - Job 8: Subtask check_snowflake_version
[2025-06-27T12:56:42.299+0000] {logging_mixin.py:188} WARNING - /home/***/.local/lib/python3.8/site-packages/***/settings.py:194 DeprecationWarning: The sql_alchemy_conn option in [core] has been moved to the sql_alchemy_conn option in [database] - the old setting has been used, but please update your config.
[2025-06-27T12:56:42.325+0000] {task_command.py:423} INFO - Running <TaskInstance: simple_snowflake_dag.check_snowflake_version manual__2025-06-27T12:56:40.724097+00:00 [running]> on host 4594cae8c2a2
[2025-06-27T12:56:42.376+0000] {taskinstance.py:2480} INFO - Exporting env vars: AIRFLOW_CTX_DAG_OWNER='***' AIRFLOW_CTX_DAG_ID='simple_snowflake_dag' AIRFLOW_CTX_TASK_ID='check_snowflake_version' AIRFLOW_CTX_EXECUTION_DATE='2025-06-27T12:56:40.724097+00:00' AIRFLOW_CTX_TRY_NUMBER='1' AIRFLOW_CTX_DAG_RUN_ID='manual__2025-06-27T12:56:40.724097+00:00'
[2025-06-27T12:56:42.377+0000] {sql.py:276} INFO - Executing: SELECT CURRENT_DATABASE();
[2025-06-27T12:56:42.386+0000] {base.py:83} INFO - Using connection ID 'my_snowflake_conn' for task execution.
[2025-06-27T12:56:42.394+0000] {base.py:83} INFO - Using connection ID 'my_snowflake_conn' for task execution.
[2025-06-27T12:56:42.395+0000] {connection.py:370} INFO - Snowflake Connector for Python Version: 3.6.0, Python Version: 3.8.18, Platform: Linux-6.2.0-26-generic-x86_64-with-glibc2.34
[2025-06-27T12:56:42.396+0000] {connection.py:1171} INFO - This connection is in OCSP Fail Open Mode. TLS Certificates would be checked for validity and revocation status. Any other Certificate Revocation related exceptions or OCSP Responder failures would be disregarded in favor of connectivity.
[2025-06-27T12:56:45.032+0000] {taskinstance.py:2698} ERROR - Task failed with exception
Traceback (most recent call last):
  File "/home/airflow/.local/lib/python3.8/site-packages/airflow/models/taskinstance.py", line 433, in _execute_task
    result = execute_callable(context=context, **execute_callable_kwargs)
  File "/home/airflow/.local/lib/python3.8/site-packages/airflow/providers/common/sql/operators/sql.py", line 282, in execute
    output = hook.run(
  File "/home/airflow/.local/lib/python3.8/site-packages/airflow/providers/snowflake/hooks/snowflake.py", line 382, in run
    with closing(self.get_conn()) as conn:
  File "/home/airflow/.local/lib/python3.8/site-packages/airflow/providers/snowflake/hooks/snowflake.py", line 276, in get_conn
    conn = connector.connect(**conn_config)
  File "/home/airflow/.local/lib/python3.8/site-packages/snowflake/connector/__init__.py", line 54, in Connect
    return SnowflakeConnection(**kwargs)
  File "/home/airflow/.local/lib/python3.8/site-packages/snowflake/connector/connection.py", line 413, in __init__
    self.connect(**kwargs)
  File "/home/airflow/.local/lib/python3.8/site-packages/snowflake/connector/connection.py", line 703, in connect
    self.__open_connection()
  File "/home/airflow/.local/lib/python3.8/site-packages/snowflake/connector/connection.py", line 1006, in __open_connection
    self.authenticate_with_retry(self.auth_class)
  File "/home/airflow/.local/lib/python3.8/site-packages/snowflake/connector/connection.py", line 1277, in authenticate_with_retry
    self._authenticate(auth_instance)
  File "/home/airflow/.local/lib/python3.8/site-packages/snowflake/connector/connection.py", line 1305, in _authenticate
    auth.authenticate(
  File "/home/airflow/.local/lib/python3.8/site-packages/snowflake/connector/auth/_auth.py", line 250, in authenticate
    ret = self._rest._post_request(
  File "/home/airflow/.local/lib/python3.8/site-packages/snowflake/connector/network.py", line 729, in _post_request
    ret = self.fetch(
  File "/home/airflow/.local/lib/python3.8/site-packages/snowflake/connector/network.py", line 838, in fetch
    ret = self._request_exec_wrapper(
  File "/home/airflow/.local/lib/python3.8/site-packages/snowflake/connector/network.py", line 974, in _request_exec_wrapper
    raise e
  File "/home/airflow/.local/lib/python3.8/site-packages/snowflake/connector/network.py", line 879, in _request_exec_wrapper
    return_object = self._request_exec(
  File "/home/airflow/.local/lib/python3.8/site-packages/snowflake/connector/network.py", line 1188, in _request_exec
    raise err
  File "/home/airflow/.local/lib/python3.8/site-packages/snowflake/connector/network.py", line 1130, in _request_exec
    raise_failed_request_error(
  File "/home/airflow/.local/lib/python3.8/site-packages/snowflake/connector/network.py", line 238, in raise_failed_request_error
    Error.errorhandler_wrapper(
  File "/home/airflow/.local/lib/python3.8/site-packages/snowflake/connector/errors.py", line 290, in errorhandler_wrapper
    handed_over = Error.hand_to_other_handler(
  File "/home/airflow/.local/lib/python3.8/site-packages/snowflake/connector/errors.py", line 348, in hand_to_other_handler
    connection.errorhandler(connection, cursor, error_class, error_value)
  File "/home/airflow/.local/lib/python3.8/site-packages/snowflake/connector/errors.py", line 221, in default_errorhandler
    raise error_class(
snowflake.connector.errors.InterfaceError: 250003 (08001): None: 404 Not Found: post https://ZM46186.snowflakecomputing.com:443/session/v1/login-request?request_id=a210db4a-c6a3-49c5-b342-4498befc1102&databaseName=AIRFLOW_PRACTICE&schemaName=PUBLIC&warehouse=COMPUTE_WH&roleName=ACCOUNTADMIN&request_guid=85a4a629-90bd-452f-a92d-b1f22da581cb
[2025-06-27T12:56:45.042+0000] {taskinstance.py:1138} INFO - Marking task as FAILED. dag_id=simple_snowflake_dag, task_id=check_snowflake_version, execution_date=20250627T125640, start_date=20250627T125642, end_date=20250627T125645
[2025-06-27T12:56:45.059+0000] {standard_task_runner.py:107} ERROR - Failed to execute job 8 for task check_snowflake_version (250003 (08001): None: 404 Not Found: post https://ZM46186.snowflakecomputing.com:443/session/v1/login-request?request_id=a210db4a-c6a3-49c5-b342-4498befc1102&databaseName=AIRFLOW_PRACTICE&schemaName=PUBLIC&warehouse=COMPUTE_WH&roleName=ACCOUNTADMIN&request_guid=85a4a629-90bd-452f-a92d-b1f22da581cb; 610)
[2025-06-27T12:56:45.072+0000] {local_task_job_runner.py:234} INFO - Task exited with return code 1
[2025-06-27T12:56:45.097+0000] {taskinstance.py:3280} INFO - 0 downstream tasks scheduled from follow-on schedule check
